<?xml version="1.0"?>
<robot name="diff_robot">

  <!-- ================= BASE ================= -->
  <link name="base_link">
    <visual>
      <geometry>
        <box size="0.5 0.3 0.2"/>
      </geometry>
      <material name="Gray"/>
    </visual>

    <collision>
      <geometry>
        <box size="0.5 0.3 0.2"/>
      </geometry>
    </collision>

    <inertial>
      <mass value="10.0"/>
      <origin xyz="0 0 0"/>
      <inertia
        ixx="0.1" ixy="0.0" ixz="0.0"
        iyy="0.1" iyz="0.0"
        izz="0.1"/>
    </inertial>
  </link>

  <!-- ================= LEFT WHEEL ================= -->
  <link name="left_wheel">
    <visual>
      <geometry>
        <cylinder radius="0.05" length="0.02"/>
      </geometry>
    </visual>

    <collision>
      <geometry>
        <cylinder radius="0.05" length="0.02"/>
      </geometry>
    </collision>

    <inertial>
      <mass value="1.0"/>
      <inertia
        ixx="0.001" ixy="0.0" ixz="0.0"
        iyy="0.001" iyz="0.0"
        izz="0.001"/>
    </inertial>
  </link>

  <!-- ================= RIGHT WHEEL ================= -->
  <link name="right_wheel">
    <visual>
      <geometry>
        <cylinder radius="0.05" length="0.02"/>
      </geometry>
    </visual>

    <collision>
      <geometry>
        <cylinder radius="0.05" length="0.02"/>
      </geometry>
    </collision>

    <inertial>
      <mass value="1.0"/>
      <inertia
        ixx="0.001" ixy="0.0" ixz="0.0"
        iyy="0.001" iyz="0.0"
        izz="0.001"/>
    </inertial>
  </link>

  <!-- ================= JOINTS ================= -->
  <joint name="left_wheel_joint" type="continuous">
    <parent link="base_link"/>
    <child link="left_wheel"/>
    <origin xyz="0 0.15 0"/>
    <axis xyz="0 1 0"/>
  </joint>

  <joint name="right_wheel_joint" type="continuous">
    <parent link="base_link"/>
    <child link="right_wheel"/>
    <origin xyz="0 -0.15 0"/>
    <axis xyz="0 1 0"/>
  </joint>

  <!-- ================= GAZEBO PLUGIN ================= -->
 <gazebo>
  <plugin name="diff_drive" filename="libgazebo_ros_diff_drive.so">

    <!-- Joints -->
    <left_joint>left_wheel_joint</left_joint>
    <right_joint>right_wheel_joint</right_joint>

    <!-- Geometry -->
    <wheel_separation>0.30</wheel_separation>
    <wheel_diameter>0.10</wheel_diameter>

    <!-- Command -->
    <cmd_vel_topic>cmd_vel</cmd_vel_topic>

    <!-- ODOMETRY (CORRECT NAMES) -->
    <publish_odom>true</publish_odom>
    <odom_topic>odom</odom_topic>
    <odom_frame>odom</odom_frame>
    <base_frame_id>base_link</base_frame_id>
    <odometry_source>world</odometry_source>

    <!-- TF -->
    <publish_tf>true</publish_tf>

    <!-- Rate -->
    <update_rate>50</update_rate>

  </plugin>
</gazebo>
</robot>
